[[34m2024-04-22 06:12:47,449[0m] {[34mscheduler_job.py:[0m714} INFO[0m - Starting the scheduler[0m
[[34m2024-04-22 06:12:47,450[0m] {[34mscheduler_job.py:[0m719} INFO[0m - Processing each file at most -1 times[0m
[[34m2024-04-22 06:12:47,451[0m] {[34mexecutor_loader.py:[0m107} INFO[0m - Loaded executor: SequentialExecutor[0m
[[34m2024-04-22 06:12:47,456[0m] {[34mmanager.py:[0m163} INFO[0m - Launched DagFileProcessorManager with pid: 43192[0m
[[34m2024-04-22 06:12:47,457[0m] {[34mscheduler_job.py:[0m1408} INFO[0m - Resetting orphaned tasks for active dag runs[0m
[[34m2024-04-22 06:12:47,461[0m] {[34msettings.py:[0m58} INFO[0m - Configured default timezone Timezone('UTC')[0m
[2024-04-22T06:12:47.474+0000] {manager.py:409} WARNING - Because we cannot use more than 1 thread (parsing_processes = 2) when using sqlite. So we set parallelism to 1.
[[34m2024-04-22 06:13:02,250[0m] {[34mserve_logs.py:[0m60} WARNING[0m - The Authorization header is missing: Accept: text/html,application/xhtml+xml,application/xml;q=0.9,image/avif,image/webp,image/apng,*/*;q=0.8,application/signed-exchange;v=b3;q=0.7
Host: localhost:8793
User-Agent: Mozilla/5.0 (Windows NT 10.0; Win64; x64) AppleWebKit/537.36 (KHTML, like Gecko) Chrome/123.0.0.0 Safari/537.36
Accept-Encoding: gzip, deflate, br, zstd
Accept-Language: en-GB,en-US;q=0.9,en;q=0.8
Cache-Control: max-age=0
Referer: https://github.com/
X-Request-Id: 5531a88677372daaf31fa713fa720c40
X-Real-Ip: 10.240.1.166
X-Forwarded-Port: 443
X-Forwarded-Scheme: https
X-Original-Uri: /
X-Scheme: https
Sec-Fetch-Site: cross-site
Sec-Fetch-Mode: navigate
Sec-Fetch-Dest: document
Sec-Ch-Ua: "Google Chrome";v="123", "Not:A-Brand";v="8", "Chromium";v="123"
Sec-Ch-Ua-Mobile: ?0
Sec-Ch-Ua-Platform: "Windows"
X-Original-Proto: https
X-Forwarded-Proto: https
X-Forwarded-Host: orange-robot-x4grjqr9x9v36rv4-8793.app.github.dev
X-Forwarded-For: 10.240.1.166
Proxy-Connection: Keep-Alive

.[0m
[[34m2024-04-22 06:13:02,251[0m] {[34mserve_logs.py:[0m104} WARNING[0m - Unknown error[0m
Traceback (most recent call last):
  File "/usr/local/python/3.10.13/lib/python3.10/site-packages/airflow/utils/serve_logs.py", line 61, in validate_pre_signed_url
    abort(403)
  File "/usr/local/python/3.10.13/lib/python3.10/site-packages/flask/helpers.py", line 310, in abort
    current_app.aborter(code, *args, **kwargs)
  File "/usr/local/python/3.10.13/lib/python3.10/site-packages/werkzeug/exceptions.py", line 864, in __call__
    raise self.mapping[code](*args, **kwargs)
werkzeug.exceptions.Forbidden: 403 Forbidden: You don't have the permission to access the requested resource. It is either read-protected or not readable by the server.[0m
[[34m2024-04-22 06:13:02,693[0m] {[34mserve_logs.py:[0m60} WARNING[0m - The Authorization header is missing: Accept: image/avif,image/webp,image/apng,image/svg+xml,image/*,*/*;q=0.8
Host: localhost:8793
User-Agent: Mozilla/5.0 (Windows NT 10.0; Win64; x64) AppleWebKit/537.36 (KHTML, like Gecko) Chrome/123.0.0.0 Safari/537.36
Accept-Encoding: gzip, deflate, br, zstd
Accept-Language: en-GB,en-US;q=0.9,en;q=0.8
Referer: https://orange-robot-x4grjqr9x9v36rv4-8793.app.github.dev/
X-Request-Id: 6f899d59f5d2f65591e606ec3ffd9cde
X-Real-Ip: 10.240.1.166
X-Forwarded-Port: 443
X-Forwarded-Scheme: https
X-Original-Uri: /favicon.ico
X-Scheme: https
Sec-Ch-Ua: "Google Chrome";v="123", "Not:A-Brand";v="8", "Chromium";v="123"
Sec-Ch-Ua-Mobile: ?0
Sec-Ch-Ua-Platform: "Windows"
Sec-Fetch-Site: same-origin
Sec-Fetch-Mode: no-cors
Sec-Fetch-Dest: image
X-Original-Proto: https
X-Forwarded-Proto: https
X-Forwarded-Host: orange-robot-x4grjqr9x9v36rv4-8793.app.github.dev
X-Forwarded-For: 10.240.1.166
Proxy-Connection: Keep-Alive

.[0m
[[34m2024-04-22 06:13:02,694[0m] {[34mserve_logs.py:[0m104} WARNING[0m - Unknown error[0m
Traceback (most recent call last):
  File "/usr/local/python/3.10.13/lib/python3.10/site-packages/airflow/utils/serve_logs.py", line 61, in validate_pre_signed_url
    abort(403)
  File "/usr/local/python/3.10.13/lib/python3.10/site-packages/flask/helpers.py", line 310, in abort
    current_app.aborter(code, *args, **kwargs)
  File "/usr/local/python/3.10.13/lib/python3.10/site-packages/werkzeug/exceptions.py", line 864, in __call__
    raise self.mapping[code](*args, **kwargs)
werkzeug.exceptions.Forbidden: 403 Forbidden: You don't have the permission to access the requested resource. It is either read-protected or not readable by the server.[0m
[[34m2024-04-22 06:17:47,828[0m] {[34mscheduler_job.py:[0m1408} INFO[0m - Resetting orphaned tasks for active dag runs[0m
[[34m2024-04-22 06:22:47,875[0m] {[34mscheduler_job.py:[0m1408} INFO[0m - Resetting orphaned tasks for active dag runs[0m
[[34m2024-04-22 06:27:48,043[0m] {[34mscheduler_job.py:[0m1408} INFO[0m - Resetting orphaned tasks for active dag runs[0m
[[34m2024-04-22 06:27:56,871[0m] {[34mscheduler_job.py:[0m179} INFO[0m - Exiting gracefully upon receiving signal 15[0m
[[34m2024-04-22 06:27:57,874[0m] {[34mprocess_utils.py:[0m129} INFO[0m - Sending Signals.SIGTERM to group 43192. PIDs of all processes in the group: [43192][0m
[[34m2024-04-22 06:27:57,875[0m] {[34mprocess_utils.py:[0m84} INFO[0m - Sending the signal Signals.SIGTERM to group 43192[0m
[[34m2024-04-22 06:27:58,095[0m] {[34mprocess_utils.py:[0m79} INFO[0m - Process psutil.Process(pid=43192, status='terminated', exitcode=0, started='06:12:47') (43192) terminated with exit code 0[0m
[[34m2024-04-22 06:27:58,097[0m] {[34mprocess_utils.py:[0m129} INFO[0m - Sending Signals.SIGTERM to group 43192. PIDs of all processes in the group: [][0m
[[34m2024-04-22 06:27:58,097[0m] {[34mprocess_utils.py:[0m84} INFO[0m - Sending the signal Signals.SIGTERM to group 43192[0m
[[34m2024-04-22 06:27:58,098[0m] {[34mprocess_utils.py:[0m98} INFO[0m - Sending the signal Signals.SIGTERM to process 43192 as process group is missing.[0m
[[34m2024-04-22 06:27:58,098[0m] {[34mscheduler_job.py:[0m788} INFO[0m - Exited execute loop[0m
